Workbook

Sheet সারসংক্ষেপ
B1: সাপ্তাহিক বৃক্ষরোপণ কর্মসূচির অগ্রগতি প্রতিবেদন
B2: কৃষি সম্প্রসারণ অধিদপ্তর (DAE), কুড়িগ্রাম জেলা | ৫ বছরে ২৫ কোটি বৃক্ষরোপণ কর্মসূচি
B3: প্রতিবেদন প্রস্তুতের তারিখ: 11 August, 2026 | প্রস্তুতকারী: উপপরিচালকের কার্যালয়, কুড়িগ্রাম
B5: মোট এন্ট্রি সংখ্যা | E5: মোট রোপণকৃত বৃক্ষ | G5: অন্তর্ভুক্ত উপজেলা
B6: =COUNTA(মূল_ডাটা!A2:A947)+COUNTA(১৭_কলাম_প্রতিবেদন!$R$5:$R$1333) -> 2275 | E6: =SUM(মূল_ডাটা!E2:E947)+SUM(১৭_কলাম_প্রতিবেদন!$H$5:$H$1333) -> 15412 | G6: 9
B7: ৯টি উপজেলার মধ্যে
B9: ক. সম্মিলিত উপজেলাভিত্তিক অগ্রগতি (দুই উৎসের একত্রীকরণ)
B10: উপজেলার নাম | C10: মূল_ডাটা এন্ট্রি | D10: মূল_ডাটা গাছ | E10: ১৭-কলাম এন্ট্রি | F10: ১৭-কলাম গাছ | G10: সম্মিলিত এন্ট্রি | H10: সম্মিলিত গাছ
B11: ভূরুঙ্গামারী | C11: =COUNTIF(মূল_ডাটা!$C$2:$C$947,$B11) -> 410 | D11: =SUMIF(মূল_ডাটা!$C$2:$C$947,$B11,মূল_ডাটা!$E$2:$E$947) -> 2050 | E11: =COUNTIF(১৭_কলাম_প্রতিবেদন!$E$5:$E$1333,$B11) -> 412 | F11: =SUMIF(১৭_কলাম_প্রতিবেদন!$E$5:$E$1333,$B11,১৭_কলাম_প্রতিবেদন!$H$5:$H$1333) -> 2438 | G11: =C11+E11 -> 822 | H11: =D11+F11 -> 4488
B12: চর রাজিবপুর | C12: =COUNTIF(মূল_ডাটা!$C$2:$C$947,$B12) -> 223 | D12: =SUMIF(মূল_ডাটা!$C$2:$C$947,$B12,মূল_ডাটা!$E$2:$E$947) -> 1115 | E12: =COUNTIF(১৭_কলাম_প্রতিবেদন!$E$5:$E$1333,$B12) -> 197 | F12: =SUMIF(১৭_কলাম_প্রতিবেদন!$E$5:$E$1333,$B12,১৭_কলাম_প্রতিবেদন!$H$5:$H$1333) -> 1513 | G12: =C12+E12 -> 420 | H12: =D12+F12 -> 2628
B13: ফুলবাড়ী | C13: =COUNTIF(মূল_ডাটা!$C$2:$C$947,$B13) -> 60 | D13: =SUMIF(মূল_ডাটা!$C$2:$C$947,$B13,মূল_ডাটা!$E$2:$E$947) -> 300 | E13: =COUNTIF(১৭_কলাম_প্রতিবেদন!$E$5:$E$1333,$B13) -> 324 | F13: =SUMIF(১৭_কলাম_প্রতিবেদন!$E$5:$E$1333,$B13,১৭_কলাম_প্রতিবেদন!$H$5:$H$1333) -> 1998 | G13: =C13+E13 -> 384 | H13: =D13+F13 -> 2298
B14: উলিপুর | C14: =COUNTIF(মূল_ডাটা!$C$2:$C$947,$B14) -> 0 | D14: =SUMIF(মূল_ডাটা!$C$2:$C$947,$B14,মূল_ডাটা!$E$2:$E$947) -> 0 | E14: =COUNTIF(১৭_কলাম_প্রতিবেদন!$E$5:$E$1333,$B14) -> 176 | F14: =SUMIF(১৭_কলাম_প্রতিবেদন!$E$5:$E$1333,$B14,১৭_কলাম_প্রতিবেদন!$H$5:$H$1333) -> 2123 | G14: =C14+E14 -> 176 | H14: =D14+F14 -> 2123
B15: চিলমারী | C15: =COUNTIF(মূল_ডাটা!$C$2:$C$947,$B15) -> 0 | D15: =SUMIF(মূল_ডাটা!$C$2:$C$947,$B15,মূল_ডাটা!$E$2:$E$947) -> 0 | E15: =COUNTIF(১৭_কলাম_প্রতিবেদন!$E$5:$E$1333,$B15) -> 140 | F15: =SUMIF(১৭_কলাম_প্রতিবেদন!$E$5:$E$1333,$B15,১৭_কলাম_প্রতিবেদন!$H$5:$H$1333) -> 1024 | G15: =C15+E15 -> 140 | H15: =D15+F15 -> 1024
B16: কুড়িগ্রাম সদর | C16: =COUNTIF(মূল_ডাটা!$C$2:$C$947,$B16) -> 110 | D16: =SUMIF(মূল_ডাটা!$C$2:$C$947,$B16,মূল_ডাটা!$E$2:$E$947) -> 150 | E16: =COUNTIF(১৭_কলাম_প্রতিবেদন!$E$5:$E$1333,$B16) -> 16 | F16: =SUMIF(১৭_কলাম_প্রতিবেদন!$E$5:$E$1333,$B16,১৭_কলাম_প্রতিবেদন!$H$5:$H$1333) -> 532 | G16: =C16+E16 -> 126 | H16: =D16+F16 -> 682
B17: রৌমারী | C17: =COUNTIF(মূল_ডাটা!$C$2:$C$947,$B17) -> 72 | D17: =SUMIF(মূল_ডাটা!$C$2:$C$947,$B17,মূল_ডাটা!$E$2:$E$947) -> 360 | E17: =COUNTIF(১৭_কলাম_প্রতিবেদন!$E$5:$E$1333,$B17) -> 50 | F17: =SUMIF(১৭_কলাম_প্রতিবেদন!$E$5:$E$1333,$B17,১৭_কলাম_প্রতিবেদন!$H$5:$H$1333) -> 628 | G17: =C17+E17 -> 122 | H17: =D17+F17 -> 988
B18: নাগেশ্বরী | C18: =COUNTIF(মূল_ডাটা!$C$2:$C$947,$B18) -> 40 | D18: =SUMIF(মূল_ডাটা!$C$2:$C$947,$B18,মূল_ডাটা!$E$2:$E$947) -> 200 | E18: =COUNTIF(১৭_কলাম_প্রতিবেদন!$E$5:$E$1333,$B18) -> 4 | F18: =SUMIF(১৭_কলাম_প্রতিবেদন!$E$5:$E$1333,$B18,১৭_কলাম_প্রতিবেদন!$H$5:$H$1333) -> 398 | G18: =C18+E18 -> 44 | H18: =D18+F18 -> 598
B19: রাজারহাট | C19: =COUNTIF(মূল_ডাটা!$C$2:$C$947,$B19) -> 31 | D19: =SUMIF(মূল_ডাটা!$C$2:$C$947,$B19,মূল_ডাটা!$E$2:$E$947) -> 155 | E19: =COUNTIF(১৭_কলাম_প্রতিবেদন!$E$5:$E$1333,$B19) -> 4 | F19: =SUMIF(১৭_কলাম_প্রতিবেদন!$E$5:$E$1333,$B19,১৭_কলাম_প্রতিবেদন!$H$5:$H$1333) -> 398 | G19: =C19+E19 -> 35 | H19: =D19+F19 -> 553
B20: অন্যান্য (জেলার বাইরে/অজ্ঞাত) | C20: 0 | D20: 0 | E20: =COUNTIF(১৭_কলাম_প্রতিবেদন!$S$5:$S$1333,"*জেলার বাইরের*")+COUNTIF(১৭_কলাম_প্রতিবেদন!$S$5:$S$1333,"*উপজেলা খালি*") -> 6 | F20: =SUMIF(১৭_কলাম_প্রতিবেদন!$S$5:$S$1333,"*জেলার বাইরের*",১৭_কলাম_প্রতিবেদন!$H$5:$H$1333)+SUMIF(১৭_কলাম_প্রতিবেদন!$S$5:$S$1333,"*উপজেলা খালি*",১৭_কলাম_প্রতিবেদন!$H$5:$H$1333) -> 30 | G20: =C20+E20 -> 6 | H20: =D20+F20 -> 30
B21: মোট | C21: =SUM(C11:C20) -> 946 | D21: =SUM(D11:D20) -> 4330 | E21: =SUM(E11:E20) -> 1329 | F21: =SUM(F11:F20) -> 11082 | G21: =SUM(G11:G20) -> 2275 | H21: =SUM(H11:H20) -> 15412
B22: নোট: "মূল_ডাটা" (ministry report, ৯৪৬ এন্ট্রি/৪,৩৩০ গাছ) ও "১৭_কলাম_প্রতিবেদন" (১,৩২৯ এন্ট্রি/১১,০৮২ গাছ) — দুই ভিন্ন উৎসের এন্ট্রি ও গাছ সংখ্যা একত্রে দেখানো হয়েছে।
B40: খ. উৎসভিত্তিক তুলনা (Source Comparison)
B41: তথ্য উৎস (শীট) | C41: এন্ট্রি সংখ্যা | D41: মোট চারা/বৃক্ষ সংখ্যা | E41: বিবরণ
B42: মূল_ডাটা (ministry report) | C42: =COUNTA(মূল_ডাটা!A2:A947) -> 946 | D42: =SUM(মূল_ডাটা!E2:E947) -> 4330 | E42: মিশ্র প্যাকেজ ও একক প্রজাতি — ৯টি উপজেলা (৭টিতে এন্ট্রি)
B43: ১৭_কলাম_প্রতিবেদন (17 column report) | C43: =COUNTA(১৭_কলাম_প্রতিবেদন!$R$5:$R$1333) -> 1329 | D43: =SUM(১৭_কলাম_প্রতিবেদন!$H$5:$H$1333) -> 11082 | E43: ফলদ/ঔষধি/বনজ ক্যাটাগরি — ৯টি উপজেলার সবকটিতেই এন্ট্রি
B44: সম্মিলিত সর্বমোট | C44: =C42+C43 -> 2275 | D44: =D42+D43 -> 15412 | E44: উভয় প্রতিবেদনের সমন্বিত ফলাফল
B45: নোট: ১৭_কলাম_প্রতিবেদনে উলিপুর ও চিলমারী উপজেলাতেও এন্ট্রি রয়েছে, ফলে দুই উৎস একত্রে করলে ৯টি উপজেলাই কভার হয়।
B47: গ. চারা/বৃক্ষের প্রজাতিভিত্তিক বিবরণ (ক্যাটাগরি)
B48: প্রজাতির ক্যাটাগরি | C48: উৎস | D48: এন্ট্রি সংখ্যা | E48: মোট চারা সংখ্যা
B49: মিশ্র প্যাকেজ | C49: মূল_ডাটা | D49: =COUNTIF(মূল_ডাটা!$K$2:$K$947,"মিশ্র প্যাকেজ") -> 846 | E49: =SUMIF(মূল_ডাটা!$K$2:$K$947,"মিশ্র প্যাকেজ",মূল_ডাটা!$E$2:$E$947) -> 4230
B50: একক প্রজাতি এন্ট্রি | C50: মূল_ডাটা | D50: =COUNTIF(মূল_ডাটা!$K$2:$K$947,"একক প্রজাতি") -> 100 | E50: =SUMIF(মূল_ডাটা!$K$2:$K$947,"একক প্রজাতি",মূল_ডাটা!$E$2:$E$947) -> 100
B51: মিশ্র প্যাকেজ | C51: ১৭_কলাম_প্রতিবেদন | D51: =COUNTIF(১৭_কলাম_প্রতিবেদন!$R$5:$R$1333,"মিশ্র প্যাকেজ") -> 610 | E51: =SUMIF(১৭_কলাম_প্রতিবেদন!$R$5:$R$1333,"মিশ্র প্যাকেজ",১৭_কলাম_প্রতিবেদন!$H$5:$H$1333) -> 3058
B52: ফলদ | C52: ১৭_কলাম_প্রতিবেদন | D52: =COUNTIF(১৭_কলাম_প্রতিবেদন!$R$5:$R$1333,"ফলদ") -> 563 | E52: =SUMIF(১৭_কলাম_প্রতিবেদন!$R$5:$R$1333,"ফলদ",১৭_কলাম_প্রতিবেদন!$H$5:$H$1333) -> 7320
B53: ঔষধি | C53: ১৭_কলাম_প্রতিবেদন | D53: =COUNTIF(১৭_কলাম_প্রতিবেদন!$R$5:$R$1333,"ঔষধি") -> 92 | E53: =SUMIF(১৭_কলাম_প্রতিবেদন!$R$5:$R$1333,"ঔষধি",১৭_কলাম_প্রতিবেদন!$H$5:$H$1333) -> 408
B54: বনজ | C54: ১৭_কলাম_প্রতিবেদন | D54: =COUNTIF(১৭_কলাম_প্রতিবেদন!$R$5:$R$1333,"বনজ") -> 62 | E54: =SUMIF(১৭_কলাম_প্রতিবেদন!$R$5:$R$1333,"বনজ",১৭_কলাম_প্রতিবেদন!$H$5:$H$1333) -> 286
B55: অন্যান্য | C55: ১৭_কলাম_প্রতিবেদন | D55: =COUNTIF(১৭_কলাম_প্রতিবেদন!$R$5:$R$1333,"অন্যান্য") -> 2 | E55: =SUMIF(১৭_কলাম_প্রতিবেদন!$R$5:$R$1333,"অন্যান্য",১৭_কলাম_প্রতিবেদন!$H$5:$H$1333) -> 10
B56: মোট | D56: =SUM(D49:D55) -> 2275 | E56: =SUM(E49:E55) -> 15412
B58: ঘ. ডাটা মান যাচাই (১৭_কলাম_প্রতিবেদন)
B59: মানদণ্ড | C59: এন্ট্রি সংখ্যা | D59: সব এন্ট্রির % | E59: মন্তব্য
B60: মোট যাচাইকৃত এন্ট্রি | C60: =COUNTA(১৭_কলাম_প্রতিবেদন!$R$5:$R$1333) -> 1329 | D60: 100% | E60: ১,৩২৯টি এন্ট্রির প্রতিটি যাচাই করা হয়েছে
B61: সিরিয়াল নম্বর অনুপস্থিত | C61: =COUNTIF(১৭_কলাম_প্রতিবেদন!$S$5:$S$1333,"*সিরিয়াল*") -> 18 | D61: =IFERROR(C61/$C$60,0) -> 0.013544018 | E61: উৎস ফাইলে #N/A ছিল
...

Sheet মূল_ডাটা
A1: ক্রঃ নং | B1: বৃক্ষরোপণের স্থান (গ্রাম/ইউনিয়ন/উপজেলা/জেলা) | C1: উপজেলা | D1: প্রজাতির নাম | E1: রোপণকৃত সংখ্যা | F1: জিওগ্রাফিক্যাল কোঅর্ডিনেট | G1: পরিচর্যাকারী কৃষক (নাম ও ফোন) | H1: এসএএও (নাম ও ফোন) | I1: মনিটরিং অফিসার (নাম ও ফোন) | J1: মন্তব্য | K1: প্রজাতি ক্যাটাগরি
A2: 1 | B2: বদরপুর, রাজিবপুর, চর রাজিবপুর, কুড়িগ্রাম। | C2: চর রাজিবপুর | D2: আম, কাঠাল, নিম, জলপাই ও মেহগনি | E2: 5 | F2: 25.46272-89.80184 | G2: মোঃ জাহিদুল ইসলাম ১৯৫৪২৭৮৭৫৮ | H2: মোঃ নজরুল ইসলাম ১৯১৭১৮৬৬৮৫ | I2: দিপক দেব নাথ ১৭৩৮৩৮৫৮১৯ | K2: মিশ্র প্যাকেজ
A3: 2 | B3: বদরপুর, রাজিবপুর, চর রাজিবপুর, কুড়িগ্রাম। | C3: চর রাজিবপুর | D3: আম, কাঠাল, নিম, জলপাই ও মেহগনি | E3: 5 | F3: 25.4597-89.80306 | G3: মোঃ আশরাফুল ইসলাম ০১৯৩৪৯২৯৫৩৩ | H3: মোঃ নজরুল ইসলাম ১৯১৭১৮৬৬৮৫ | I3: দিপক দেব নাথ ১৭৩৮৩৮৫৮১৯ | K3: মিশ্র প্যাকেজ
A4: 3 | B4: বদরপুর, রাজিবপুর, চর রাজিবপুর, কুড়িগ্রাম। | C4: চর রাজিবপুর | D4: আম, কাঠাল, নিম, জলপাই ও মেহগনি | E4: 5 | F4: 25.46249-89.80164 | G4: মোঃ গোলাম মোস্তফা ০১৯৮৯৮৩৫৬৯১ | H4: মোঃ নজরুল ইসলাম ১৯১৭১৮৬৬৮৫ | I4: দিপক দেব নাথ ১৭৩৮৩৮৫৮১৯ | K4: মিশ্র প্যাকেজ
A5: 4 | B5: বদরপুর, রাজিবপুর, চর রাজিবপুর, কুড়িগ্রাম। | C5: চর রাজিবপুর | D5: আম, কাঠাল, নিম, জলপাই ও মেহগনি | E5: 5 | F5: 25.4616-89.8001 | G5: মোঃ ইব্রাহীম মিয়া ০১৯১৯৪৩০০৩১ | H5: মোঃ নজরুল ইসলাম ১৯১৭১৮৬৬৮৫ | I5: দিপক দেব নাথ ১৭৩৮৩৮৫৮১৯ | K5: মিশ্র প্যাকেজ
A6: 5 | B6: বদরপুর, রাজিবপুর, চর রাজিবপুর, কুড়িগ্রাম। | C6: চর রাজিবপুর | D6: আম, কাঠাল, নিম, জলপাই ও মেহগনি | E6: 5 | F6: 25.45859-89.80315 | G6: মোঃ হাবিবুর রহমান ০১৯৩৪৯২৮৭০৮ | H6: মোঃ নজরুল ইসলাম ১৯১৭১৮৬৬৮৫ | I6: দিপক দেব নাথ ১৭৩৮৩৮৫৮১৯ | K6: মিশ্র প্যাকেজ
A7: 6 | B7: বদরপুর, রাজিবপুর, চর রাজিবপুর, কুড়িগ্রাম। | C7: চর রাজিবপুর | D7: আম, কাঠাল, নিম, জলপাই ও মেহগনি | E7: 5 | F7: 25.46175-89.80015 | G7: মোঃ ইয়াছিন আলী ০১৭২৬৭৬০১৪৪ | H7: মোঃ নজরুল ইসলাম ১৯১৭১৮৬৬৮৫ | I7: দিপক দেব নাথ ১৭৩৮৩৮৫৮১৯ | K7: মিশ্র প্যাকেজ
A8: 7 | B8: বদরপুর, রাজিবপুর, চর রাজিবপুর, কুড়িগ্রাম। | C8: চর রাজিবপুর | D8: আম, কাঠাল, নিম, জলপাই ও মেহগনি | E8: 5 | F8: 25.4626-89.8012 | G8: মোঃ শাহাদত হোসেন ০১৯১৯৪৩০০৩১ | H8: মোঃ নজরুল ইসলাম ১৯১৭১৮৬৬৮৫ | I8: দিপক দেব নাথ ১৭৩৮৩৮৫৮১৯ | K8: মিশ্র প্যাকেজ
A9: 8 | B9: বদরপুর, রাজিবপুর, চর রাজিবপুর, কুড়িগ্রাম। | C9: চর রাজিবপুর | D9: আম, কাঠাল, নিম, জলপাই ও মেহগনি | E9: 5 | F9: 25.44285-89.78961 | G9: মোঃ আঃ ছাত্তার ০১৬১৪৯৮৬৬০৬ | H9: মোঃ নজরুল ইসলাম ১৯১৭১৮৬৬৮৫ | I9: দিপক দেব নাথ ১৭৩৮৩৮৫৮১৯ | K9: মিশ্র প্যাকেজ
A10: 9 | B10: বদরপুর, রাজিবপুর, চর রাজিবপুর, কুড়িগ্রাম। | C10: চর রাজিবপুর | D10: আম, কাঠাল, নিম, জলপাই ও মেহগনি | E10: 5 | F10: 25.46239-89.80166 | G10: মোঃ সিরাজুল ইসলাম ০১৯৩০৩৯০৪৪২ | H10: মোঃ নজরুল ইসলাম ১৯১৭১৮৬৬৮৫ | I10: দিপক দেব নাথ ১৭৩৮৩৮৫৮১৯ | K10: মিশ্র প্যাকেজ
A11: 10 | B11: বদরপুর, রাজিবপুর, চর রাজিবপুর, কুড়িগ্রাম। | C11: চর রাজিবপুর | D11: আম, কাঠাল, নিম, জলপাই ও মেহগনি | E11: 5 | F11: 25.46215-89.80161 | G11: মোঃ ছয়নুদ্দিন ০১৯৪৩০৭১৯২২ | H11: মোঃ নজরুল ইসলাম ১৯১৭১৮৬৬৮৫ | I11: দিপক দেব নাথ ১৭৩৮৩৮৫৮১৯ | K11: মিশ্র প্যাকেজ
A12: 11 | B12: করাতিপাড়া, রাজিবপুর, চর রাজিবপুর, কুড়িগ্রাম। | C12: চর রাজিবপুর | D12: আম, কাঠাল, নিম, জলপাই ও মেহগনি | E12: 5 | F12: 25.44121-89.78539 | G12: মোছাঃ সুলতানা পারভীন ০১৯৮৯৩৩৯৫৭৬ | H12: মোঃ নজরুল ইসলাম ১৯১৭১৮৬৬৮৫ | I12: দিপক দেব নাথ ১৭৩৮৩৮৫৮১৯ | K12: মিশ্র প্যাকেজ
A13: 12 | B13: আজগড় দেওয়ানীপাড়া, রাজিবপুর, চর রাজিবপুর, কুড়িগ্রাম। | C13: চর রাজিবপুর | D13: আম, কাঠাল, নিম, জলপাই ও মেহগনি | E13: 5 | F13: 25.44401-89.78675 | G13: মোঃ ছরোয়ার হোসেন ০১৯০৩১২৪৮৮১ | H13: মোঃ নজরুল ইসলাম ১৯১৭১৮৬৬৮৫ | I13: দিপক দেব নাথ ১৭৩৮৩৮৫৮১৯ | K13: মিশ্র প্যাকেজ
... A389: 388 | B389: গ্রামঃপশ্চিম দেবত্তর ইউনিয়নঃ ঘড়িয়ালডাঙ্গা , উপজেলাঃ রাজারহাট, জেলাঃ কুড়িগ্রাম। | C389: রাজারহাট | D389: আম (আমরুপালী), কাঠাল, নিম, জলপাই (হাইব্রীড) ও মেহগনি | E389: 5 | F389: 25.804018, 89.489072 | G389: কষ্ণ কমল, ০১৭৫৫১০৩০৭৫ | H389: রামকৃষ্ণ রায়, ০১৭১৭৬৭৭৫২৩ | I389: হৈমন্তী রানী, ০১৭৪৫৫০৬৫২২ | K389: মিশ্র প্যাকেজ
A390: 389 | B390: ব্যাপারী টারি , কেদার, নাগেশ্বরী, কুড়িগ্রাম | C390: নাগেশ্বরী | D390: আম, জাম, কাঁঠাল, মেহগনি, নিম | E390: 5 | F390: 26.035136,89.779144 | G390: আফজাল হোসেন, 1728826489 | H390: খন্দকার মোশারফ হোসেন, 1718878257 | J390: 15.07.26 | K390: মিশ্র প্যাকেজ
A391: 390 | B391: ব্যাপারী টারি , কেদার, নাগেশ্বরী, কুড়িগ্রাম | C391: নাগেশ্বরী | D391: আম, জাম, কাঁঠাল, মেহগনি, নিম | E391: 5 | F391: 26.035071,89.777057 | G391: বেলাল হোসেন, 1717030972 | H391: খন্দকার মোশারফ হোসেন, 1718878257 | J391: 15.07.26 | K391: মিশ্র প্যাকেজ
A392: 391 | B392: ঢলুয়াবাড়ি , কেদার, নাগেশ্বরী, কুড়িগ্রাম | C392: নাগেশ্বরী | D392: আম, জাম, কাঁঠাল, মেহগনি, নিম | E392: 5 | F392: 26.034747,89778279 | G392: রোকসানা বেগম, | H392: খন্দকার মোশারফ হোসেন, 1718878257 | J392: 15.07.26 | K392: মিশ্র প্যাকেজ
A393: 392 | B393: ব্যাপারী টারি, কেদার, নাগেশ্বরী, কুড়িগ্রাম | C393: নাগেশ্বরী | D393: আম, জাম, কাঁঠাল, মেহগনি, নিম | E393: 5 | F393: 26.034062,89.777857 | G393: রিয়াজুল ইসলাম, 1765262331 | H393: খন্দকার মোশারফ হোসেন, 1718878257 | J393: 15.07.26 | K393: মিশ্র প্যাকেজ
A394: 393 | B394: ব্যাপারী টারি, কেদার, নাগেশ্বরী, কুড়িগ্রাম | C394: নাগেশ্বরী | D394: আম, জাম, কাঁঠাল, মেহগনি, নিম | E394: 5 | F394: 26.033880,89.778226 | G394: সিরাজুল ইসলাম, 1723881600 | H394: খন্দকার মোশারফ হোসেন, 1718878257 | J394: 15.07.26 | K394: মিশ্র প্যাকেজ
A395: 394 | B395: বাহের কেদার , কেদার, নাগেশ্বরী, কুড়িগ্রাম | C395: নাগেশ্বরী | D395: আম, জাম, কাঁঠাল, মেহগনি, নিম | E395: 5 | F395: 26.037311,89.775876 | G395: দুলাল হোসেন, 1722699557 | H395: খন্দকার মোশারফ হোসেন, 1718878257 | J395: 15.07.26 | K395: মিশ্র প্যাকেজ
A396: 395 | B396: বাহের কেদার , কেদার, নাগেশ্বরী, কুড়িগ্রাম | C396: নাগেশ্বরী | D396: আম, জাম, কাঁঠাল, মেহগনি, নিম | E396: 5 | F396: 26.034948,89.777754 | G396: সিরাজুল ইসলাম, 1750848760 | H396: খন্দকার মোশারফ হোসেন, 1718878257 | J396: 15.07.26 | K396: মিশ্র প্যাকেজ
A397: 396 | B397: ঢলুয়াবাড়ি , কেদার, নাগেশ্বরী, কুড়িগ্রাম | C397: নাগেশ্বরী | D397: আম, জাম, কাঁঠাল, মেহগনি, নিম | E397: 5 | F397: 26.044875,89.774223 | G397: রফিকুল ইসলাম, 1740280429 | H397: খন্দকার মোশারফ হোসেন, 1718878257 | J397: 15.07.26 | K397: মিশ্র প্যাকেজ
A398: 397 | B398: কাইম টেপার কুটি , কেদার, নাগেশ্বরী, কুড়িগ্রাম | C398: নাগেশ্বরী | D398: আম, জাম, কাঁঠাল, মেহগনি, নিম | E398: 5 | F398: 26.033587,89.777578 | G398: জাহাঙ্গীর আলম, 1775818745 | H398: মো: আবু তারেক, 01737456407 | J398: 15.07.26 | K398: মিশ্র প্যাকেজ
A399: 398 | B399: ঢলুয়াবাড়ি , কেদার, নাগেশ্বরী, কুড়িগ্রাম | C399: নাগেশ্বরী | D399: আম, জাম, কাঁঠাল, মেহগনি, নিম | E399: 5 | F399: 26.047296,89.760559 | G399: নুর হক, 1763160528 | H399: খন্দকার মোশারফ হোসেন, 1718878257 | J399: 15.07.26 | K399: মিশ্র প্যাকেজ
A400: 399 | B400: ঢলুয়াবাড়ি , কেদার, নাগেশ্বরী, কুড়িগ্রাম | C400: নাগেশ্বরী | D400: আম, জাম, কাঁঠাল, মেহগনি, নিম | E400: 5 | F400: 26.034088,89.777402 | G400: ফরিদুল ইসলাম, 1763269319 | H400: খন্দকার মোশারফ হোসেন, 1718878257 | J400: 15.07.26 | K400: মিশ্র প্যাকেজ
A401: 400 | B401: ঢলুয়াবাড়ি , কেদার, নাগেশ্বরী, কুড়িগ্রাম | C401: নাগেশ্বরী | D401: আম, জাম, কাঁঠাল, মেহগনি, নিম | E401: 5 | F401: 26.047088,89.760358 | G401: আব্দুর রশিদ, 1776937129 | H401: খন্দকার মোশারফ হোসেন, 1718878257 | J401: 15.07.26 | K401: মিশ্র প্যাকেজ
... A419: 418 | B419: ঢলুয়াবাড়ি , কেদার, নাগেশ্বরী, কুড়িগ্রাম | C419: নাগেশ্বরী | D419: আম, জাম, কাঁঠাল, মেহগনি, নিম | E419: 5 | F419: 26.029895,89.804720 | G419: আজিবর রহমান, 1313336971 | H419: খন্দকার মোশারফ হোসেন, 1718878257 | J419: 15.07.26 | K419: মিশ্র প্যাকেজ
A420: 419 | B420: ঘোগারকুটি, বড়ভিটা, বড়ভিটা, ফুলবাড়ী | C420: ফুলবাড়ী | D420: আম, কাঠাল, জাম, নিম, মেহগনি | E420: 5 | F420: 25.915910, 89.574561 | G420: সবুজ মিয়া, 01739377334 | H420: উদয় কৃষ্ণ রায় | I420: মোঃ আব্দুল্লাহ আল মামুন, 01710474405 | K420: মিশ্র প্যাকেজ
A421: 420 | B421: ঘোগারকুটি, বড়ভিটা, বড়ভিটা | C421: ফুলবাড়ী | D421: আম, কাঠাল, জাম, নিম, মেহগনি | E421: 5 | F421: 25.916715, 89.569462 | G421: হারুন অর রশিদ, 01744399668 | H421: উদয় কৃষ্ণ রায় | I421: মোঃ আব্দুল্লাহ আল মামুন, ০১৭১০৪৭৪৪০৬ | K421: মিশ্র প্যাকেজ
A422: 421 | B422: পাতারুটারী, বড়ভিটা, বড়ভিটা | C422: ফুলবাড়ী | D422: আম, কাঠাল, জাম, নিম, মেহগনি | E422: 5 | F422: 25.907532, 89.572085 | G422: মকছেদুল হক, 01794806824 | H422: উদয় কৃষ্ণ রায় | I422: মোঃ আব্দুল্লাহ আল মামুন, ০১৭১০৪৭৪৪০৭ | K422: মিশ্র প্যাকেজ
A423: 422 | B423: ঘোগারকুটি, বড়ভিটা, বড়ভিটা | C423: ফুলবাড়ী | D423: আম, কাঠাল, জাম, নিম, মেহগনি | E423: 5 | F423: 25.914172, 89.570327 | G423: সাধনা রানী, 01737170745 | H423: উদয় কৃষ্ণ রায় | I423: মোঃ আব্দুল্লাহ আল মামুন, ০১৭১০৪৭৪৪০৮ | K423: মিশ্র প্যাকেজ
A424: 423 | B424: ঘোগারকুটি, বড়ভিটা, বড়ভিটা | C424: ফুলবাড়ী | D424: আম, কাঠাল, জাম, নিম, মেহগনি | E424: 5 | F424: 25.907676, 89.572093 | G424: শেফালী বেগম, 01761072837 | H424: উদয় কৃষ্ণ রায় | I424: মোঃ আব্দুল্লাহ আল মামুন, ০১৭১০৪৭৪৪০৯ | K424: মিশ্র প্যাকেজ
A425: 424 | B425: ঘোগারকুটি, বড়ভিটা, বড়ভিটা | C425: ফুলবাড়ী | D425: আম, কাঠাল, জাম, নিম, মেহগনি | E425: 5 | F425: 25.918662, 89.569796 | G425: রবিউল ইসলাম, 01734197848 | H425: উদয় কৃষ্ণ রায় | I425: মোঃ আব্দুল্লাহ আল মামুন, ০১৭১০৪৭৪৪১০ | K425: মিশ্র প্যাকেজ
A426: 425 | B426: নওদাবশ, বড়ভিটা, বড়ভিটা | C426: ফুলবাড়ী | D426: আম, কাঠাল, জাম, নিম, মেহগনি | E426: 5 | F426: 25.917379, 89.51731 | G426: লিটন চন্দ্র, 01788279002 | H426: উদয় কৃষ্ণ রায় | I426: মোঃ আব্দুল্লাহ আল মামুন, ০১৭১০৪৭৪৪১১ | K426: মিশ্র প্যাকেজ
A427: 426 | B427: নওদাবশ, বড়ভিটা, বড়ভিটা | C427: ফুলবাড়ী | D427: আম, কাঠাল, জাম, নিম, মেহগনি | E427: 5 | F427: 25.918513, 89.594006 | G427: মমিনুল ইসলাম, 01733462455 | H427: উদয় কৃষ্ণ রায় | I427: মোঃ আব্দুল্লাহ আল মামুন, ০১৭১০৪৭৪৪১২ | K427: মিশ্র প্যাকেজ
A428: 427 | B428: নওদাবশ, বড়ভিটা, বড়ভিটা | C428: ফুলবাড়ী | D428: আম, কাঠাল, জাম, নিম, মেহগনি | E428: 5 | F428: 25.916527, 89.590755 | G428: পলাশ কুমার, 01750549630 | H428: উদয় কৃষ্ণ রায় | I428: মোঃ আব্দুল্লাহ আল মামুন, ০১৭১০৪৭৪৪১৩ | K428: মিশ্র প্যাকেজ
A429: 428 | B429: নওদাবশ, বড়ভিটা, বড়ভিটা | C429: ফুলবাড়ী | D429: আম, কাঠাল, জাম, নিম, মেহগনি | E429: 5 | F429: 25.921551, 89.587194 | G429: অঞ্জনা, 01737803051 | H429: উদয় কৃষ্ণ রায় | I429: মোঃ আব্দুল্লাহ আল মামুন, ০১৭১০৪৭৪৪১৪ | K429: মিশ্র প্যাকেজ
A430: 429 | B430: নওদাবশ, বড়ভিটা, বড়ভিটা | C430: ফুলবাড়ী | D430: আম, কাঠাল, জাম, নিম, মেহগনি | E430: 5 | F430: 25.916759, 89.592764 | G430: মেরিনা বেগম, 01750066531 | H430: উদয় কৃষ্ণ রায় | I430: মোঃ আব্দুল্লাহ আল মামুন, ০১৭১০৪৭৪৪১৫ | K430: মিশ্র প্যাকেজ
A431: 430 | B431: বড়ভিটা, বড়ভিটা, বড়ভিটা | C431: ফুলবাড়ী | D431: আম, কাঠাল, জাম, নিম, মেহগনি | E431: 5 | F431: 25.903954, 89.581964 | G431: ওহাব আলী, 01752101216 | H431: উদয় কৃষ্ণ রায় | I431: মোঃ আব্দুল্লাহ আল মামুন, ০১৭১০৪৭৪৪১৬ | K431: মিশ্র প্যাকেজ
... A571: 570 | B571: গ্রাম : শিলখুড়ি ইউনিয়ন : শিলখুড়ি উপজেলা: ভূরুঙ্গামারী জেলা : কুড়িগ্রাম | C571: ভূরুঙ্গামারী | D571: আম (আমরুপালী), কাঠাল, নিম, জলপাই (হাইব্রীড) ও মেহগনি | E571: 5 | F571: 26.206821,89.660142 | G571: জাহিদুল ০১৭৯১৩৩৫১৯৯ | H571: মোঃ সাদ্দাম হোসেন, ০১৭৩৮১৫৫১৭৮ | I571: মোঃ আব্দুল জব্বার ০১৭২২৬৮৩২৯১ | K571: মিশ্র প্যাকেজ
...

Sheet ১৭_কলাম_প্রতিবেদন
A1: ১৭. ০৫ বছরে ২৫ কোটি বৃক্ষ রোপণ কর্মসূচির আওতায় রোপণকৃত চারার তথ্য
A2: মন্ত্রণালয়/বিভাগ/অধিদপ্তর: কৃষি সম্প্রসারণ অধিদপ্তর, কুড়িগ্রাম জেলা | বিভাগ: রংপুর | মাস: August | তারিখ: 11 Aug 2026
A4: ক্র. নং | B4: গ্রামের নাম | C4: ব্লক | D4: ইউনিয়ন | E4: উপজেলা | F4: জেলা | G4: প্রজাতির নাম | H4: চারার সংখ্যা | I4: রোপণের তারিখ | J4: জিওগ্রাফিক্যাল কো-অর্ডিনেট | K4: কৃষকের নাম | L4: কৃষকের মোবাইল | M4: SAAO-এর নাম | N4: SAAO-এর মোবাইল | O4: মনিটরিং অফিসারের নাম | P4: মনিটরিং মোবাইল | Q4: মন্তব্য | R4: প্রজাতি ক্যাটাগরি | S4: ডাটা মান যাচাই
A5: 1 | B5: ভুরুঙ্গামারী | D5: মোগলবাসা | E5: কুড়িগ্রাম সদর | F5: কুড়িগ্রাম | G5: পেয়ারা থাই-৭ (ফলদ) × 85 | H5: 85 | I5: 10 May 2026 | J5: 25.755591,89.657639 | K5: মোঃ রেজওয়ান সরকার | L5: 01750674891 | M5: ভবেশ চন্দ্র মোদক | N5: 01724511968 | O5: দিপু রায় | P5: ০১৭৩৭৬৬৫৩৩১ | R5: ফলদ
A6: 2 | B6: কাঁঠালবাড়ী | D6: কাঁঠালবাড়ী | E6: কুড়িগ্রাম সদর | F6: কুড়িগ্রাম | G6: মাল্টা বারি-১ (ফলদ) × 60 | H6: 60 | I6: 4 Jun 2026 | J6: 25.826721,89.603292 | K6: মোঃ আতিকুর রহমান | L6: 01727620179 | M6: নারায়ন চন্দ্র সরকার | N6: 01724511346 | O6: দিপু রায় | P6: ০১৭৩৭৬৬৫৩৩১ | R6: ফলদ
A7: 3 | B7: হলোখানা | D7: হলোখানা | E7: কুড়িগ্রাম সদর | F7: কুড়িগ্রাম | G7: লেবু সিডরেস (ফলদ) × 220 | H7: 220 | I7: 2 Jun 2026 | J7: 25.830043,89.6245 | K7: মোঃ আমিনুর ইসলাম | L7: 01723360770 | M7: এস এম تরিকুল ইসলাম | N7: 01716026306 | O7: দিপু রায় | P7: ০১৭৩৭৬৬৫৩৩১ | R7: ফলদ
A8: 4 | B8: বেলগাছা | D8: বেলগাছা | E8: কুড়িগ্রাম সদর | F8: কুড়িগ্রাম | G8: আম-ব্যানানা (ফলদ) × 33 | H8: 33 | I8: 2 Jun 2026 | J8: 25.79392,89.62017 | K8: জয়ন্তী রাণী | L8: 01791966821 | M8: মোঃ নুর আলম | N8: 01729451848 | O8: দিপু রায় | P8: ০১৭৩৭৬৬৫৩৩১ | R8: ফলদ
A9: 5 | B9: চর ভুরুঙ্গামারী | D9: চর ভুরুঙ্গামারী | E9: ভূরুঙ্গামারী | F9: কুড়িগ্রাম | G9: আম-ব্যানানা মেঙ্গো (ফলদ) × 33 | H9: 33 | I9: 2 Jun 2026 | J9: 26.125547,89.729581 | K9: মোছা: শারমিন আক্তার | L9: 01712046367 | M9: মো: মঞ্জুরুল ইসলাম | N9: 01717813138 | R9: ফলদ | S9: মনিটরিং অফিসার খালি
A10: 6 | B10: পাইকেরছড়া | D10: পাইকেরছড়া | E10: ভূরুঙ্গামারী | F10: কুড়িগ্রাম | G10: পেয়ারা- গোল্ডেন-৮ (ফলদ) × 85 | H10: 85 | I10: 26 May 2026 | J10: 26.09305,89.69845 | K10: মোছা: অনিকা বেগম | L10: 01774361298 | M10: মো: শাহানুর আলম | N10: 01737084908 | R10: ফলদ | S10: মনিটরিং অফিসার খালি
A11: 7 | B11: পাথরডুবি | D11: পাথরডুবি | E11: ভূরুঙ্গামারী | F11: কুড়িগ্রাম | G11: মাল্টা- বারি-১ (ফলদ) × 60 | H11: 60 | I11: 1 Jun 2026 | J11: 26.125547,89.621771 | K11: মোছা: আখি আক্তার | L11: 01642860652 | M11: মো: আবুল বাশার | N11: 01303614632 | R11: ফলদ | S11: মনিটরিং অফিসার খালি
A12: 8 | B12: জয়মনিরহাট | D12: জয়মনিরহাট | E12: ভূরুঙ্গামারী | F12: কুড়িগ্রাম | G12: লেবু-সিটলেজ (ফলদ) × 220 | H12: 220 | I12: 3 Jun 2026 | J12: 26.068899,89.673812 | K12: মো: সফিকুল ইসলাম | L12: 01774361415 | M12: মো: শহিদুল ইসলাম | N12: 01737458464 | R12: ফলদ | S12: মনিটরিং অফিসার খালি
A13: 9 | B13: কোদালকাটি | D13: কোদালকাটি | E13: চর রাজিবপুর | F13: কুড়িগ্রাম | G13: আম (আমরুপালী) (ফলদ) × 33 | H13: 33 | I13: 4 May 2026 | J13: 25.482715,89.768447 | K13: সিরাজুল ইসলাম | L13: 01718165491 | M13: মোঃ শাখাওয়াত হোসেন | N13: 01743668680 | R13: ফলদ | S13: মনিটরিং অফিসার খালি
A14: 10 | B14: রাজিবপুর | D14: রাজিবপুর | E14: চর রাজিবপুর | F14: কুড়িগ্রাম | G14: পেয়ারা (কাজী) (ফলদ) × 85 | H14: 85 | I14: 5 May 2026 | J14: 25.459003,89.828174 | K14: মোঃ শাহ আলম | L14: 01956402022 | M14: মোঃ শাখাওয়াত হোসেন | N14: 01743668680 | R14: ফলদ | S14: মনিটরিং অফিসার খালি
A15: 11 | B15: মোহনগঞ্জ | D15: মোহনগঞ্জ | E15: চর রাজিবপুর | F15: কুড়িগ্রাম | G15: মাল্টা (বারি মাল্টা-1) (ফলদ) × 60 | H15: 60 | I15: 6 May 2026 | J15: 25.427144,89.771586 | K15: মোঃ জহুরুল হক | L15: 01937371604 | M15: মোঃ শাখাওয়াত হোসেন | N15: 1743668680 | R15: ফলদ | S15: মনিটরিং অফিসার খালি
A16: 12 | B16: রাজিবপুর | D16: রাজিবপুর | E16: চর রাজিবপুর | F16: কুড়িগ্রাম | G16: লেবু (দেশী) (ফলদ) × 370 | H16: 370 | I16: 7 May 2026 | J16: 25.436446,89.777963 | K16: মোঃ আলমগীর হোসেন | L16: 01935305296 | M16: মোঃ শাখাওয়াত হোসেন | N16: 1743668680 | R16: ফলদ | S16: মনিটরিং অফিসার খালি
A17: 13 | B17: দলদলিয়া | D17: দলদলিয়া | E17: উলিপুর | F17: কুড়িগ্রাম | G17: থাই পেয়ারা (ফলদ) × 85 | H17: 85 | I17: 11 May 2026 | J17: 25.719195,89.552201 | K17: মোঃ নবিউল ইসলাম | L17: 01714925452 | M17: মোঃ শাহ আলম | N17: 1740147853 | R17: ফলদ | S17: মনিটরিং অফিসার খালি
A18: 14 | B18: ধামশ্রেণী | D18: ধামশ্রেণী | E18: উলিপুর | F18: কুড়িগ্রাম | G18: বারি মাল্টা-১ (ফলদ) × 60 | H18: 60 | I18: 16 May 2026 | J18: 25.656067,89.648548 | K18: মোঃ ফজলে কাদীর | L18: 01751373251 | M18: মোঃ গোলজার হোসেন | N18: 1724264812 | R18: ফলদ | S18: মনিটরিং অফিসার খালি
A19: 15 | B19: ধরণীবাড়ী | D19: ধরণীবাড়ী | E19: উলিপুর | F19: কুড়িগ্রাম | G19: লেবু চায়না-৩ (ফলদ) × 220 | H19: 220 | I19: 20 May 2026 | J19: 25.690651,89.61554 | K19: মোঃ মাসুদ رানা | L19: 01731439180 | M19: মোঃ শওকত আলী | N19: 01710050829 | R19: ফলদ | S19: মনিটরিং অফিসার খালি
A20: 16 | B20: তবকপুর | D20: গুনাইগাছ | E20: উলিপুর | F20: কুড়িগ্রাম | G20: বারি আম-4 (ফলদ) × 33 | H20: 33 | I20: 18 May 2026 | J20: 25.642387,89.617095 | K20: মোছাঃ শামীম আক্তার আমিন | L20: 01794664933 | M20: মোঃ শওকত আলী | N20: 01710050829 | R20: ফলদ | S20: মনিটরিং অফিসার খালি
... A40: 36 | B40: চাকিরপশার | D40: চাকিরপশার | E40: রাজারহাট | F40: কুড়িগ্রাম | G40: লেবু সিডরেস (ফলদ) × 220 | H40: 220 | I40: 12 Jun 2026 | J40: 25.7915,89.5412 | K40: মো: দুলাল মিয়া | L40: 01724591382 | M40: মোঃ আমজাদ হোসেন | N40: 01718253491 | R40: ফলদ | S40: মনিটরিং অফিসার খালি
A41: 37 | B41: বেলগাছা | D41: মোগলবাসা | E41: কুড়িগ্রাম সদর | F41: কুড়িগ্রাম | G41: আম (ফলদ) × 30 | H41: 30 | I41: 26 Jun 2026 | J41: 25.802833,89.638069 | K41: মোঃ আখতার হোসেন | L41: 01794829595 | M41: মাহফুজ আহমেদ | O41: মোঃ সারওয়ার হোসেন | P41: 01737358851 | R41: ফলদ
A42: 38 | B42: বেলগাছা | D42: মোগলবাসা | E42: কুড়িগ্রাম সদর | F42: কুড়িগ্রাম | G42: আম (ফলদ) × 5 | H42: 5 | I42: 9 Jul 2026 | J42: 25.802903,89.637888 | K42: মনু মিয়া | L42: 01748485819 | M42: নজরুল ইসলাম | N42: 01765856589 | O42: দিপক দেব নাথ | P42: 01738385819 | R42: ফলদ
A43: 39 | B43: বেলগাছা | D43: মোগলবাসা | E43: কুড়িগ্রাম সদর | F43: কুড়িগ্রাম | G43: আম (ফলদ) × 1 | H43: 5 | I43: 8 Jul 2026 | J43: 25.802876,89.638004 | K43: গনেশ | L43: 01979183491 | M43: মোছাঃ সোহানা খাতুন | N43: 01310582141 | O43: MD. MAIDUL HASAN | P43: 01723183491 | R43: ফলদ
A44: 40 | B44: বেলগাছা | D44: মোগলবাসা | E44: কুড়িগ্রাম সদর | F44: কুড়িগ্রাম | G44: আম (ফলদ) × 33 | H44: 33 | I44: 4 Jul 2026 | J44: 25.802889,89.638051 | K44: মো: আতাউর | L44: 01710050829 | O44: মোছা: আফরোজা পারভীন রিফা | P44: 01784143269 | R44: ফলদ
A45: 41 | B45: বেলগাছা | D45: মোগলবাসা | E45: কুড়িগ্রাম সদর | F45: কুড়িগ্রাম | G45: আম (ফলদ) × 1 | H45: 5 | I45: 9 Jul 2026 | J45: 25.802832,89.638074 | K45: মোখলেসুর রহমান | L45: 01703450989 | M45: মাহফুজর রহমান | N45: 01796786131 | O45: মোঃ মনিরুজ্জামান | P45: 01736576367 | R45: ফলদ
A46: 42 | B46: বেলগাছা | D46: মোগলবাসা | E46: কুড়িগ্রাম সদর | F46: কুড়িগ্রাম | G46: জাম (ফলদ) × 30 | H46: 30 | J46: 25.802449,89.637573 | K46: লাভলু | L46: 01722677811 | O46: মোঃ ফিরোজ হোসেন | P46: 01758772809 | R46: ফলদ | S46: রোপণের তারিখ খালি
A47: 43 | B47: বেলগাছা | D47: মোগলবাসা | E47: কুড়িগ্রাম সদর | F47: কুড়িগ্রাম | G47: আম (ফলদ) × 1 | H47: 5 | I47: 2 Jul 2026 | J47: 25.803479,89.637668 | K47: আবুল | L47: 01725505536 | M47: রাসেল | O47: হৈমন্তী রানী | P47: 01745506522 | R47: ফলদ
A48: 44 | B48: বেলগাছা | D48: মোগলবাসা | E48: কুড়িগ্রাম সদর | F48: কুড়িগ্রাম | G48: আম (ফলদ) × 1 | H48: 1 | I48: 9 Jul 2026 | J48: 25.803489,89.637743 | K48: জয়ন্তী রানী | L48: 01737665332 | M48: মো: নূর আলম | N48: 01737665332 | O48: দিপু রায | P48: 01737665331 | R48: ফলদ
A49: 45 | B49: বেলগাছা | D49: মোগলবাসা | E49: কুড়িগ্রাম সদর | F49: কুড়িগ্রাম | G49: লেবু (ফলদ) × 2 | H49: 5 | I49: 2 Jul 2026 | J49: 25.802847,89.638053 | K49: ওসমান গনি | L49: 01733452846 | M49: আসাদুজ্জামান | N49: 01738227622 | O49: মো: আব্দুল্লাহ আল মামুন | P49: 01710474405 | R49: ফলদ
A50: 46 | B50: বেলগাছা | D50: মোগলবাসা | E50: কুড়িগ্রাম সদর | F50: কুড়িগ্রাম | G50: আম (ফলদ) × 5 | H50: 5 | I50: 7 Jul 2026 | J50: 25.802921,89.637911 | K50: নবিউল | L50: 01741457151 | M50: শওকত আলী | N50: 01374147151 | O50: মোছাঃ খালেদা খাতুন | P50: 01334031177 | R50: ফলদ
A51: 47 | B51: বেলগাছা | D51: মোগলবাসা | E51: কুড়িগ্রাম সদর | F51: কুড়িগ্রাম | G51: আম (ফলদ) × 5 | H51: 5 | I51: 1 Jul 2026 | J51: 25.802882,89.637927 | K51: মোঃ সারওয়ার হোসেন | L51: 01737358851 | O51: মোঃ৷ সারওয়ার হোসেন | P51: 01737358851 | R51: ফলদ
A52: 48 | B52: রাজিবপুর | D52: রাজিবপুর | E52: চর রাজিবপুর | F52: কুড়িগ্রাম | G52: নারিকেল (ফলদ) × 5 | H52: 5 | I52: 12 Jul 2026 | J52: 22.791749,89.462178 | K52: বাবলু বিশ্বাস | L52: 01715849869 | M52: শেখ আবু হুরায়রা | N52: 01925427257 | R52: ফলদ | S52: মনিটরিং অফিসার খালি
A53: 49 | B53: রাজিবপুর | D53: রাজিবপুর | E53: চর রাজিবপুর | F53: কুড়িগ্রাম | G53: নারিকেল (ফলদ) × 5 | H53: 5 | I53: 12 Jul 2026 | J53: 22.792484,89.462916 | K53: অনুপ তরফদার | L53: 01944819402 | M53: শেখ আবু হুরায়রা | N53: 01925427257 | R53: ফলদ | S53: মনিটরিং অফিসার খালি
A54: 50 | B54: রাজিবপুর | D54: রাজিবপুর | E54: চর রাজিবপুর | F54: কুড়িগ্রাম | G54: আম, কাঠাল, নিম, জলপাই ও মেহগনি (ফলদ, বনজ) × 5 | H54: 5 | J54: 25.46272,89.80184 | K54: মোঃ জাহিদুল ইসলাম | L54: ১৯৫৪২৭৮৭৫৮ | M54: মোঃ নজরুল ইসলাম | N54: ১৯১৭১৮৬৬৮৫ | O54: দিপক দেব নাথ | P54: 01738385819 | R54: মিশ্র প্যাকেজ | S54: রোপণের তারিখ খালি
A55: 51 | B55: রাজিবপুর | D55: রাজিবপুর | E55: চর রাজিবপুর | F55: কুড়িগ্রাম | G55: আম, কাঠাল, নিম, জলপাই ও মেহগনি (ফলদ, বনজ) × 5 | H55: 5 | J55: 25.4597,89.80306 | K55: মোঃ আশরাফুল ইসলাম | L55: ০১৯৩৪৯২৯৫৩৩ | M55: মোঃ নজরুল ইসলাম | N55: ১৯১৭১৮৬৬৮৫ | O55: দিপক দেব নাথ | P55: 01738385819 | R55: মিশ্র প্যাকেজ | S55: রোপণের তারিখ খালি
A56: 52 | B56: রাজিবপুর | D56: রাজিবপুর | E56: চর রাজিবপুর | F56: কুড়িগ্রাম | G56: আম, কাঠাল, নিম, জলপাই ও মেহগনি (ফলদ, বনজ) × 5 | H56: 5 | J56: 25.46249,89.80164 | K56: মোঃ গোলাম মোস্তফা | L56: ০১৯৮৯৮৩৫৬৯১ | M56: মোঃ নজরুল ইসলাম | N56: ১৯১৭১৮৬৬৮৫ | O56: দিপক দেব নাথ | P56: 01738385819 | R56: মিশ্র প্যাকেজ | S56: রোপণের তারিখ খালি
A57: 53 | B57: রাজিবপুর | D57: রাজিবপুর | E57: চর রাজিবপুর | F57: কুড়িগ্রাম | G57: আম, কাঠাল, নিম, জলপাই ও মেহগনি (ফলদ, বনজ) × 5 | H57: 5 | J57: 25.4616,89.8001 | K57: মোঃ ইব্রাহীম মিয়া | L57: ০১৯১৯৪৩০০৩১ | M57: মোঃ নজরুল ইসলাম | N57: ১৯১৭১৮৬৬৮৫ | O57: দিপক দেব নাথ | P57: 01738385819 | R57: মিশ্র প্যাকেজ | S57: রোপণের তারিখ খালি
A58: 54 | B58: রাজিবপুর | D58: রাজিবপুর | E58: চর রাজিবপুর | F58: কুড়িগ্রাম | G58: আম, কাঠাল, নিম, জলপাই ও মেহগনি (ফলদ, বনজ) × 5 | H58: 5 | J58: 25.45859,89.80315 | K58: মোঃ হাবিবুর রহমান | L58: ০১৯৩৪৯২৮৭০৮ | M58: মোঃ নজরুল ইসলাম | N58: ১৯১৭১৮৬৬৮৫ | O58: দিপক দেব নাথ | P58: 01738385819 | R58: মিশ্র প্যাকেজ | S58: রোপণের তারিখ খালি
A59: 55 | B59: রাজিবপুর | D59: রাজিবপুর | E59: চর রাজিবপুর | F59: কুড়িগ্রাম | G59: আম, কাঠাল, নিম, জলপাই ও মেহগনি (ফলদ, বনজ) × 5 | H59: 5 | J59: 25.46175,89.80015 | K59: মোঃ ইয়াছিন আলী | L59: ০১৭২৬৭৬০১৪৪ | M59: মোঃ নজরুল ইসলাম | N59: ১৯১৭১৮৬৬৮৫ | O59: দিপক দেব নাথ | P59: 1738385819 | R59: মিশ্র প্যাকেজ | S59: রোপণের তারিখ খালি
A60: 56 | B60: রাজিবপুর | D60: রাজিবপুর | E60: চর রাজিবপুর | F60: কুড়িগ্রাম | G60: আম, কাঠাল, নিম, জলপাই ও মেহগনি (ফলদ, বনজ) × 5 | H60: 5 | J60: 25.4626,89.8012 | K60: মোঃ শাহাদত হোসেন | L60: ০১৯১৯৪৩০০৩১ | M60: মোঃ নজরুল ইসলাম | N60: ১৯১৭১৮৬৬৮৫ | O60: দিপক দেব নাথ | P60: 1738385819 | R60: মিশ্র প্যাকেজ | S60: রোপণের তারিখ খালি
...
